<?xml version="1.0" ?>
<robot name="my_gripper" xmlns:xacro="http://www.ros.org/wiki/xacro">

  <!-- Include gazebo customization elements like colors and control plugins-->
  <xacro:include filename="$(find poke_description)/urdf/my_gripper.gazebo"/>
  <!-- Import materials-->
  <xacro:include filename="$(find poke_description)/urdf/materials.xacro"/>

  <link name="world"/>
  <joint name="fixed" type="fixed">
    <parent link="world"/>
    <child link="link0"/>
  </joint>
  <link name="link0">
    <visual>
      <origin rpy="0 0 0" xyz="0 0 0.45"/>
      <geometry>
        <box size="0.04 0.04 0.9"/>
      </geometry>
    </visual>
    <collision>
      <origin rpy="0 0 0" xyz="0 0 0.45"/>
      <geometry>
        <box size="0.04 0.04 0.9"/>
      </geometry>
    </collision>
    <inertial>
      <origin rpy="0 0 0" xyz="0 0 0.45"/>
      <mass value="0.1"/>
      <inertia ixx="0.002" ixy="0" ixz="0" iyy="0.002" iyz="0" izz="0.002"/>
    </inertial>
  </link>

  <joint name="joint1" type="prismatic">
    <origin xyz="0 0.04 0.45" rpy="0 0 0"/>
    <parent link="link0"/>
    <child link="link1"/>
    <axis xyz="0 0 1"/>
    <dynamics damping="0.7"/>
    <limit effort="300.0" lower="0" upper="0.4" velocity="2"/>
  </joint>

  <link name="link1">
    <visual>
      <origin rpy="0 0 0" xyz="0 0 0.25"/>
      <geometry>
        <box size="0.04 0.04 0.5"/>
      </geometry>
      <material name="orange"/>
    </visual>
    <collision>
      <origin rpy="0 0 0" xyz="0 0 0.25"/>
      <geometry>
        <box size="0.04 0.04 0.5"/>
      </geometry>
    </collision>
    <inertial>
      <origin rpy="0 0 0" xyz="0 0 0.25"/>
      <mass value="0.1"/>
      <inertia ixx="0.002" ixy="0" ixz="0" iyy="0.002" iyz="0" izz="0.002"/>
    </inertial>
  </link>

  <joint name="joint2" type="prismatic">
    <origin xyz="0 -0.02 0.52" rpy="${-pi/2} 0 0"/>
    <parent link="link1"/>
    <child link="link2"/>
    <axis xyz="0 0 -1"/>
    <dynamics damping="0.7"/>
    <!-- adding extra 0.05m to each limit, originally 0 to 0.80-->
    <limit effort="300.0" lower="-0.05" upper="0.85" velocity="2"/>
  </joint>

  <link name="link2">
    <visual>
      <origin rpy="0 0 0" xyz="0 0 0.41"/>
      <geometry>
        <box size="0.04 0.04 0.82"/>
      </geometry>
      <material name="black"/>
    </visual>
    <collision>
      <origin rpy="0 0 0" xyz="0 0 0.41"/>
      <geometry>
        <box size="0.04 0.04 0.82"/>
      </geometry>
    </collision>
    <inertial>
      <origin rpy="0 0 0" xyz="0 0 0.41"/>
      <mass value="0.15"/>
      <inertia ixx="0.002" ixy="0" ixz="0" iyy="0.002" iyz="0" izz="0.002"/>
    </inertial>
  </link>

  <joint name="joint3" type="prismatic">
    <origin xyz="-0.02 0 0.84" rpy="0 ${pi/2} 0"/>
    <parent link="link2"/>
    <child link="link3"/>
    <axis xyz="0 0 -1"/>
    <dynamics damping="0.7"/>
    <!-- adding extra 0.05m to each limit, originally 0 to 0.82-->
    <limit effort="300.0" lower="-0.05" upper="0.87" velocity="2"/>
  </joint>

  <link name="link3">
    <visual>
      <origin rpy="0 0 0" xyz="0 0 0.42"/>
      <geometry>
        <box size="0.04 0.04 0.84"/>
      </geometry>
      <material name="orange"/>
    </visual>
    <collision>
      <origin rpy="0 0 0" xyz="0 0 0.42"/>
      <geometry>
        <box size="0.04 0.04 0.84"/>
      </geometry>
    </collision>
    <inertial>
      <origin rpy="0 0 0" xyz="0 0 0.42"/>
      <mass value="0.16"/>
      <inertia ixx="0.002" ixy="0" ixz="0" iyy="0.002" iyz="0" izz="0.002"/>
    </inertial>
  </link>

  <joint name="my_camera_joint" type="fixed">
    <origin xyz="0.26 0.47 1.22" rpy="0 ${4*pi/9} 0"/>
    <parent link="link0"/>
    <child link="my_camera_link"/>
    <axis xyz="1 0 0 "/>
  </joint>
  <!-- Camera -->
  <link name="my_camera_link">
    <!--
    <collision>
      <origin xyz="0 0 0" rpy="0 0 0"/>
      <geometry>
        <box size="0.03 0.03 0.03"/>
      </geometry>
    </collision>
    -->
    <visual>
      <origin xyz="0 0 0" rpy="0 0 0"/>
      <geometry>
        <box size="0.03 0.03 0.03"/>
      </geometry>
      <material name="black"/>
    </visual>
    <inertial>
      <mass value="1e-2" />
      <origin xyz="0 0 0" rpy="0 0 0"/>
      <inertia ixx="1e-3" ixy="0" ixz="0" iyy="1e-3" iyz="0" izz="1e-3" />
    </inertial>
  </link>

  <transmission name="trans1">
    <type>transmission_interface/SimpleTransmission</type>
    <joint name="joint1">
      <hardwareInterface>EffortJointInterface</hardwareInterface>
    </joint>
    <actuator name="motor1">
      <hardwareInterface>EffortJointInterface</hardwareInterface>
      <mechanicalReduction>1</mechanicalReduction>
    </actuator>
  </transmission>
  <transmission name="trans2">
    <type>transmission_interface/SimpleTransmission</type>
    <joint name="joint2">
      <hardwareInterface>EffortJointInterface</hardwareInterface>
    </joint>
    <actuator name="motor2">
      <hardwareInterface>EffortJointInterface</hardwareInterface>
      <mechanicalReduction>1</mechanicalReduction>
    </actuator>
  </transmission>
  <transmission name="trans3">
    <type>transmission_interface/SimpleTransmission</type>
    <joint name="joint3">
      <hardwareInterface>EffortJointInterface</hardwareInterface>
    </joint>
    <actuator name="motor3">
      <hardwareInterface>EffortJointInterface</hardwareInterface>
      <mechanicalReduction>1</mechanicalReduction>
    </actuator>
  </transmission>

  <!-- Left End Effector -->
  <xacro:include filename="$(find poke_description)/urdf/my_electric_gripper.xacro" />
  <xacro:my_electric_gripper side="left"
                                  l_finger="extended_narrow"
                                  l_finger_slot="1"
                                  l_finger_tip="basic_soft_tip"
                                  l_finger_grasp="inner"
                                  r_finger="extended_narrow"
                                  r_finger_slot="1"
                                  r_finger_tip="basic_soft_tip"
                                  r_finger_grasp="inner"/>
</robot>
